Traceback (most recent call last):
  File "C:\Users\cross\miniconda3\lib\site-packages\jupyter_cache\executors\utils.py", line 58, in single_nb_execution
    executenb(
  File "C:\Users\cross\miniconda3\lib\site-packages\nbclient\client.py", line 1204, in execute
    return NotebookClient(nb=nb, resources=resources, km=km, **kwargs).execute()
  File "C:\Users\cross\miniconda3\lib\site-packages\nbclient\util.py", line 84, in wrapped
    return just_run(coro(*args, **kwargs))
  File "C:\Users\cross\miniconda3\lib\site-packages\nbclient\util.py", line 62, in just_run
    return loop.run_until_complete(coro)
  File "C:\Users\cross\miniconda3\lib\asyncio\base_events.py", line 647, in run_until_complete
    return future.result()
  File "C:\Users\cross\miniconda3\lib\site-packages\nbclient\client.py", line 663, in async_execute
    await self.async_execute_cell(
  File "C:\Users\cross\miniconda3\lib\site-packages\nbclient\client.py", line 965, in async_execute_cell
    await self._check_raise_for_error(cell, cell_index, exec_reply)
  File "C:\Users\cross\miniconda3\lib\site-packages\nbclient\client.py", line 862, in _check_raise_for_error
    raise CellExecutionError.from_cell_and_msg(cell, exec_reply_content)
nbclient.exceptions.CellExecutionError: An error occurred while executing the following cell:
------------------
import statistics
numbers = [a,b,c,...]

x = statistics.mean(numbers)
print("Mean is :", x)
------------------

[1;31m---------------------------------------------------------------------------[0m
[1;31mNameError[0m                                 Traceback (most recent call last)
Cell [1;32mIn [2], line 2[0m
[0;32m      1[0m [38;5;28;01mimport[39;00m [38;5;21;01mstatistics[39;00m
[1;32m----> 2[0m numbers [38;5;241m=[39m [[43ma[49m,b,c,[38;5;241m.[39m[38;5;241m.[39m[38;5;241m.[39m]
[0;32m      4[0m x [38;5;241m=[39m statistics[38;5;241m.[39mmean(numbers)
[0;32m      5[0m [38;5;28mprint[39m([38;5;124m"[39m[38;5;124mMean is :[39m[38;5;124m"[39m, x)

[1;31mNameError[0m: name 'a' is not defined
NameError: name 'a' is not defined

